myFlowerExperiment | ERROR flwr 2025-05-26 03:19:32,990 | app.py:152 | ClientApp raised an exception
Traceback (most recent call last):
  File "/home/ubuntu/anaconda3/envs/E2FL/lib/python3.10/site-packages/flwr/client/clientapp/app.py", line 137, in run_clientapp
    reply_message = client_app(message=message, context=context)
  File "/home/ubuntu/anaconda3/envs/E2FL/lib/python3.10/site-packages/flwr/client/client_app.py", line 144, in __call__
    return self._call(message, context)
  File "/home/ubuntu/anaconda3/envs/E2FL/lib/python3.10/site-packages/flwr/client/client_app.py", line 128, in ffn
    out_message = handle_legacy_message_from_msgtype(
  File "/home/ubuntu/anaconda3/envs/E2FL/lib/python3.10/site-packages/flwr/client/message_handler/message_handler.py", line 128, in handle_legacy_message_from_msgtype
    fit_res = maybe_call_fit(
  File "/home/ubuntu/anaconda3/envs/E2FL/lib/python3.10/site-packages/flwr/client/client.py", line 224, in maybe_call_fit
    return client.fit(fit_ins)
  File "/home/ubuntu/anaconda3/envs/E2FL/lib/python3.10/site-packages/flwr/client/numpy_client.py", line 227, in _fit
    results = self.numpy_client.fit(parameters, ins.config)  # type: ignore
  File "/home/ubuntu/.flwr/apps/wwjang.e2fl.1.0.0.2be7fb1e/e2fl/client_app.py", line 159, in fit
    train_loss = train(
  File "/home/ubuntu/.flwr/apps/wwjang.e2fl.1.0.0.2be7fb1e/e2fl/task.py", line 244, in train
    loss = criterion(net(images.to(device)), labels.to(device))
  File "/home/ubuntu/anaconda3/envs/E2FL/lib/python3.10/site-packages/torch/nn/modules/module.py", line 1736, in _wrapped_call_impl
    return self._call_impl(*args, **kwargs)
  File "/home/ubuntu/anaconda3/envs/E2FL/lib/python3.10/site-packages/torch/nn/modules/module.py", line 1747, in _call_impl
    return forward_call(*args, **kwargs)
  File "/home/ubuntu/anaconda3/envs/E2FL/lib/python3.10/site-packages/torchvision/models/alexnet.py", line 48, in forward
    x = self.features(x)
  File "/home/ubuntu/anaconda3/envs/E2FL/lib/python3.10/site-packages/torch/nn/modules/module.py", line 1736, in _wrapped_call_impl
    return self._call_impl(*args, **kwargs)
  File "/home/ubuntu/anaconda3/envs/E2FL/lib/python3.10/site-packages/torch/nn/modules/module.py", line 1747, in _call_impl
    return forward_call(*args, **kwargs)
  File "/home/ubuntu/anaconda3/envs/E2FL/lib/python3.10/site-packages/torch/nn/modules/container.py", line 250, in forward
    input = module(input)
  File "/home/ubuntu/anaconda3/envs/E2FL/lib/python3.10/site-packages/torch/nn/modules/module.py", line 1736, in _wrapped_call_impl
    return self._call_impl(*args, **kwargs)
  File "/home/ubuntu/anaconda3/envs/E2FL/lib/python3.10/site-packages/torch/nn/modules/module.py", line 1747, in _call_impl
    return forward_call(*args, **kwargs)
  File "/home/ubuntu/anaconda3/envs/E2FL/lib/python3.10/site-packages/torch/nn/modules/pooling.py", line 213, in forward
    return F.max_pool2d(
  File "/home/ubuntu/anaconda3/envs/E2FL/lib/python3.10/site-packages/torch/_jit_internal.py", line 624, in fn
    return if_false(*args, **kwargs)
  File "/home/ubuntu/anaconda3/envs/E2FL/lib/python3.10/site-packages/torch/nn/functional.py", line 830, in _max_pool2d
    return torch.max_pool2d(input, kernel_size, stride, padding, dilation, ceil_mode)
RuntimeError: Given input size: (256x1x1). Calculated output size: (256x0x0). Output size is too small
myFlowerExperiment | INFO flwr 2025-05-26 03:19:33,023 | app.py:222 | [flwr-clientapp] Push `ClientAppOutputs` for token 16713777071077690998
