myFlowerExperiment | ERROR flwr 2025-05-14 03:10:55,006 | app.py:152 | ClientApp raised an exception
Traceback (most recent call last):
  File "/home/ubuntu/anaconda3/envs/E2FL/lib/python3.10/site-packages/flwr/client/clientapp/app.py", line 137, in run_clientapp
    reply_message = client_app(message=message, context=context)
  File "/home/ubuntu/anaconda3/envs/E2FL/lib/python3.10/site-packages/flwr/client/client_app.py", line 144, in __call__
    return self._call(message, context)
  File "/home/ubuntu/anaconda3/envs/E2FL/lib/python3.10/site-packages/flwr/client/client_app.py", line 128, in ffn
    out_message = handle_legacy_message_from_msgtype(
  File "/home/ubuntu/anaconda3/envs/E2FL/lib/python3.10/site-packages/flwr/client/message_handler/message_handler.py", line 96, in handle_legacy_message_from_msgtype
    client = client_fn(context)
  File "/home/ubuntu/.flwr/apps/wwjang.e2fl.1.0.0.9ca534de/e2fl/client_app.py", line 284, in client_fn
    model_name = context.node_config["model"]
KeyError: 'model'
myFlowerExperiment | INFO flwr 2025-05-14 03:10:55,007 | app.py:222 | [flwr-clientapp] Push `ClientAppOutputs` for token 7924631420143306989
